<?xml version="1.0" ?>

<robot name="robot" xmlns:xacro="http://www.ros.org/wiki/xacro">

    <xacro:include filename="$(find final_project)/urdf/robot.gazebo" />

    <!-- Parameters -->
    <xacro:property name="pi" value="3.1415" />

    <!-- Link - chassis -->
    <link name="link_chassis">
        <inertial>
            <mass value="1" />
            <origin xyz="0 0 0.2" rpy="0 0 0" />
            <inertia ixx="1.5417" ixy="0" ixz="0" iyy="3.467" iyz="0" izz="4.742" />
        </inertial>

        <collision>
            <geometry>
                <box size="1 0.75 0.2" />
            </geometry>
        </collision>

        <visual>
            <geometry>
                <box size="1 0.75 0.2" />
            </geometry>
            <material name="Red">
                <color rgba="1 0 0 1" />
            </material>
        </visual>
    </link>

    <!-- Joint - chassis / rear left wheel -->
    <joint name="joint_chassis_rear_left_wheel" type="continuous">
        <origin rpy="0 0 0" xyz="-0.3 0.375 0" />
        <child link="link_rear_left_wheel" />
        <parent link="link_chassis" />
        <axis rpy="0 0 0" xyz="0 1 0" />
        <limit effort="10000" velocity="1000" />
        <joint_properties damping="1.0" friction="1.0" />
    </joint>

    <!-- Link - rear left wheel -->
    <link name="link_rear_left_wheel">
        <inertial>
            <mass value="0.5" />
            <origin xyz="0 0 0" rpy="0 0 0" />
            <inertia ixx="0.002526666666667" ixy="0" ixz="0" iyy="0.002526666666667" iyz="0" izz="0.005"/>
        </inertial>

        <collision>
            <origin rpy="${pi / 2} 0 0" xyz="0 0.1 0" />
            <geometry>
                <cylinder length="0.1" radius="0.25"/>
            </geometry>
        </collision>
        <visual>
            <origin rpy="${pi / 2} 0 0" xyz="0 0.1 0" />
            <geometry>
                <mesh filename="package://robot_description/meshes/wheel.stl" scale="0.5 0.5 0.5" />
            </geometry>
            <material name="Black">
                <color rgba="0 0 0 1" />
            </material>
        </visual>

        <collision>
            <origin rpy="${pi / 2} 0 0" xyz="0 0.0525 0" />
            <geometry>
                <cylinder length="0.105" radius="0.05"/>
            </geometry>
        </collision>
        <visual>
            <origin rpy="${pi / 2} 0 0" xyz="0 0.0525 0" />
            <geometry>
                <cylinder length="0.105" radius="0.05"/>
            </geometry>
            <material name="Black">
                <color rgba="0 0 0 1" />
            </material>
        </visual>

        <collision>
            <origin rpy="${pi} 0 0" xyz="0 0.1 0" />
            <geometry>
                <box size="0.03 0.01 0.3" />
            </geometry>
        </collision>
        <visual>
            <origin rpy="${pi} 0 0" xyz="0 0.1 0" />
            <geometry>
                <box size="0.03 0.01 0.3" />
            </geometry>
            <material name="Black">
                <color rgba="0 0 0 1" />
            </material>
        </visual>

    </link>

    <!-- Joint - chassis / front left wheel -->
    <joint name="joint_chassis_front_left_wheel" type="continuous">
        <origin rpy="0 0 0" xyz="0.3 0.375 0" />
        <child link="link_front_left_wheel" />
        <parent link="link_chassis" />
        <axis rpy="0 0 0" xyz="0 1 0" />
        <limit effort="10000" velocity="1000" />
        <joint_properties damping="1.0" friction="1.0" />
    </joint>

    <!-- Link - front left wheel -->
    <link name="link_front_left_wheel">
        <inertial>
            <mass value="0.5" />
            <origin xyz="0 0 0" rpy="0 0 0" />
            <inertia ixx="0.002526666666667" ixy="0" ixz="0" iyy="0.002526666666667" iyz="0" izz="0.005"/>
        </inertial>

        <collision>
            <origin rpy="${pi / 2} 0 0" xyz="0 0.1 0" />
            <geometry>
                <cylinder length="0.1" radius="0.25"/>
            </geometry>
        </collision>
        <visual>
            <origin rpy="${pi / 2} 0 0" xyz="0 0.1 0" />
            <geometry>
                <mesh filename="package://robot_description/meshes/wheel.stl" scale="0.5 0.5 0.5" />
            </geometry>
            <material name="Black">
                <color rgba="0 0 0 1" />
            </material>
        </visual>

        <collision>
            <origin rpy="${pi / 2} 0 0" xyz="0 0.0525 0" />
            <geometry>
                <cylinder length="0.105" radius="0.05"/>
            </geometry>
        </collision>
        <visual>
            <origin rpy="${pi / 2} 0 0" xyz="0 0.0525 0" />
            <geometry>
                <cylinder length="0.105" radius="0.05"/>
            </geometry>
            <material name="Black">
                <color rgba="0 0 0 1" />
            </material>
        </visual>

        <collision>
            <origin rpy="${pi} 0 0" xyz="0 0.1 0" />
            <geometry>
                <box size="0.03 0.01 0.3" />
            </geometry>
        </collision>
        <visual>
            <origin rpy="${pi} 0 0" xyz="0 0.1 0" />
            <geometry>
                <box size="0.03 0.01 0.3" />
            </geometry>
            <material name="Black">
                <color rgba="0 0 0 1" />
            </material>
        </visual>

    </link>

    <!-- Joint - chassis / rear right wheel -->
    <joint name="joint_chassis_rear_right_wheel" type="continuous">
        <origin rpy="0 0 0" xyz="-0.3 -0.375 0" />
        <child link="link_rear_right_wheel" />
        <parent link="link_chassis" />
        <axis rpy="0 0 0" xyz="0 1 0" />
        <limit effort="10000" velocity="1000" />
        <joint_properties damping="1.0" friction="1.0" />
    </joint>

    <!-- Link - rear right wheel -->
    <link name="link_rear_right_wheel">
        <inertial>
            <mass value="0.5" />
            <origin xyz="0 0 0" rpy="0 0 0" />
            <inertia ixx="0.002526666666667" ixy="0" ixz="0" iyy="0.002526666666667" iyz="0" izz="0.005"/>
        </inertial>

        <collision>
            <origin rpy="${pi / 2} 0 0" xyz="0 -0.1 0" />
            <geometry>
                <cylinder length="0.1" radius="0.25"/>
            </geometry>
        </collision>
        <visual>
            <origin rpy="${pi / 2} 0 0" xyz="0 -0.1 0" />
            <geometry>
                <mesh filename="package://robot_description/meshes/wheel.stl" scale="0.5 0.5 0.5" />
            </geometry>
            <material name="Black">
                <color rgba="0 0 0 1" />
            </material>
        </visual>

        <collision>
            <origin rpy="${pi / 2} 0 0" xyz="0 -0.0525 0" />
            <geometry>
                <cylinder length="0.105" radius="0.05"/>
            </geometry>
        </collision>
        <visual>
            <origin rpy="${pi / 2} 0 0" xyz="0 -0.0525 0" />
            <geometry>
                <cylinder length="0.105" radius="0.05"/>
            </geometry>
            <material name="Black">
                <color rgba="0 0 0 1" />
            </material>
        </visual>

        <collision>
            <origin rpy="${pi} 0 0" xyz="0 -0.1 0" />
            <geometry>
                <box size="0.03 0.01 0.3" />
            </geometry>
        </collision>
        <visual>
            <origin rpy="${pi} 0 0" xyz="0 -0.1 0" />
            <geometry>
                <box size="0.03 0.01 0.3" />
            </geometry>
            <material name="Black">
                <color rgba="0 0 0 1" />
            </material>
        </visual>

    </link>

    <!-- Joint - chassis / front right wheel -->
    <joint name="joint_chassis_front_right_wheel" type="continuous">
        <origin rpy="0 0 0" xyz="0.3 -0.375 0" />
        <child link="link_front_right_wheel" />
        <parent link="link_chassis" />
        <axis rpy="0 0 0" xyz="0 1 0" />
        <limit effort="10000" velocity="1000" />
        <joint_properties damping="1.0" friction="1.0" />
    </joint>

    <!-- Link - front right wheel -->
    <link name="link_front_right_wheel">
        <inertial>
            <mass value="0.5" />
            <origin xyz="0 0 0" rpy="0 0 0" />
            <inertia ixx="0.002526666666667" ixy="0" ixz="0" iyy="0.002526666666667" iyz="0" izz="0.005"/>
        </inertial>

        <collision>
            <origin rpy="${pi / 2} 0 0" xyz="0 -0.1 0" />
            <geometry>
                <cylinder length="0.1" radius="0.25"/>
            </geometry>
        </collision>
        <visual>
            <origin rpy="${pi / 2} 0 0" xyz="0 -0.1 0" />
            <geometry>
                <mesh filename="package://robot_description/meshes/wheel.stl" scale="0.5 0.5 0.5" />
            </geometry>
            <material name="Black">
                <color rgba="0 0 0 1" />
            </material>
        </visual>

        <collision>
            <origin rpy="${pi / 2} 0 0" xyz="0 -0.0525 0" />
            <geometry>
                <cylinder length="0.105" radius="0.05"/>
            </geometry>
        </collision>
        <visual>
            <origin rpy="${pi / 2} 0 0" xyz="0 -0.0525 0" />
            <geometry>
                <cylinder length="0.105" radius="0.05"/>
            </geometry>
            <material name="Black">
                <color rgba="0 0 0 1" />
            </material>
        </visual>

        <collision>
            <origin rpy="${pi} 0 0" xyz="0 -0.1 0" />
            <geometry>
                <box size="0.03 0.01 0.3" />
            </geometry>
        </collision>
        <visual>
            <origin rpy="${pi} 0 0" xyz="0 -0.1 0" />
            <geometry>
                <box size="0.03 0.01 0.3" />
            </geometry>
            <material name="Black">
                <color rgba="0 0 0 1" />
            </material>
        </visual>

    </link>

        <!-- Joint : Laser scan -->
    <joint name="joint_laser_scan_chassis" type="fixed">
        <origin rpy="0 0 0" xyz="0.8 0 0.3" />
        <child link="link_laser_scan" />
        <parent link="link_chassis" />
        <joint_properties damping="1.0" friction="1.0" />
    </joint>

    <!-- Link : Laser scan -->
    <link name="link_laser_scan">
        <inertial>
            <origin xyz="0 0 0" rpy="0 0 0" />
            <mass value="0.5" />
            <inertia ixx="0.000252666666667" ixy="0" ixz="0" iyy="0.000252666666667" iyz="0" izz="0.0005"/>
        </inertial>
        <visual>
            <origin xyz="0 0 0" rpy="0 0 0" />
            <geometry>
                <cylinder radius="0.15" length="0.20"/>
            </geometry>
            <material name="Red">
                <color rgba="0.7 0.1 0.1 1" />
            </material>
        </visual>
        <collision>
            <origin xyz="0 0 0" rpy="0 0 0"/>
            <geometry>
                <cylinder radius="0.15" length="0.20"/>
            </geometry>
        </collision>
    </link>

</robot>

